<?xml version="1.0"?>
<robot xmlns:xacro="http://www.ros.org/wiki/xacro" >

<link name="base_footprint"/>   
  
  <link
    name="chassis">
    <inertial>
      <origin
        xyz="-0.063114 -1.1102E-16 0.15305"
        rpy="0 0 0" />
      <mass
        value="45" />
      <inertia
        ixx="3.5878"
        ixy="7.9503E-16"
        ixz="0.33119"
        iyy="5.9693"
        iyz="-2.1444E-16"
        izz="6.898" />
    </inertial>
    <visual>
      <origin
        xyz="0 0 0"
        rpy="0 0 0" />
      <geometry>
        <mesh
          filename="file://$(find articubot_one)/meshes/chassis.STL" />
      </geometry>
      <material
        name="">
        <color
          rgba="0.79216 0.81961 0.93333 1" />
      </material>
    </visual>
    <collision>
      <origin
        xyz="0 0 0"
        rpy="0 0 0" />
      <geometry>
        <mesh
          filename="file://$(find articubot_one)/meshes/chassis.STL" />
      </geometry>
    </collision>
  </link>
  <link
    name="wheel1">
    <inertial>
      <origin
        xyz="2.2204E-16 0 -0.020599"
        rpy="0 0 0" />
      <mass
        value="1" />
      <inertia
        ixx="0.0015346"
        ixy="-2.7105E-20"
        ixz="1.233E-19"
        iyy="0.0015346"
        iyz="2.1433E-19"
        izz="0.0021859" />
    </inertial>
    <visual>
      <origin
        xyz="0 0 0"
        rpy="0 0 0" />
      <geometry>
        <mesh
		filename="file://$(find articubot_one)/meshes/wheel1.STL" />
      </geometry>
      <material
        name="">
        <color
          rgba="0.79216 0.81961 0.93333 1" />
      </material>
    </visual>
    <collision>
      <origin
        xyz="0 0 0"
        rpy="0 0 0" />
      <geometry>
        <mesh
          filename="file://$(find articubot_one)/meshes/wheel1.STL" />
      </geometry>
    </collision>
  </link>
  
  <joint name="base_footprint_to_chassis" type="fixed">
  <parent link="base_footprint"/>
  <child link="chassis"/>
  <origin xyz="0 0 0.25" rpy="0 0 0"/>
</joint>


  <joint
    name="wheel1_joint"
    type="continuous">
    <origin
      xyz="0.23 -0.285 -0.2"
      rpy="-1.5708 0 0" />
    <parent
      link="chassis" />
    <child
      link="wheel1" />
    <axis
      xyz="0 0 1" />
    <limit
      lower="60"
      upper="45"
      effort="7.6"
      velocity="5.24" />
    <dynamics
      damping="0.2"
      friction="0.25" />
  </joint>
  <link
    name="wheel2">
    <inertial>
      <origin
        xyz="0 0 -0.020599"
        rpy="0 0 0" />
      <mass
        value="1" />
      <inertia
        ixx="0.0015346"
        ixy="-5.421E-19"
        ixz="-8.1481E-21"
        iyy="0.0015346"
        iyz="-2.2326E-19"
        izz="0.0021859" />
    </inertial>
    <visual>
      <origin
        xyz="0 0 0"
        rpy="0 0 0" />
      <geometry>
        <mesh
          filename="file://$(find articubot_one)/meshes/wheel2.STL" />
      </geometry>
      <material
        name="">
        <color
          rgba="0.79216 0.81961 0.93333 1" />
      </material>
    </visual>
    <collision>
      <origin
        xyz="0 0 0"
        rpy="0 0 0" />
      <geometry>
        <mesh
          filename="file://$(find articubot_one)/meshes/wheel2.STL" />
      </geometry>
    </collision>
  </link>
  <joint
    name="wheel2_joint"
    type="continuous">
    <origin
      xyz="-0.23 -0.285 -0.2"
      rpy="-1.5708 0 0" />
    <parent
      link="chassis" />
    <child
      link="wheel2" />
    <axis
      xyz="0 0 1" />
    
  </joint>
  <link
    name="wheel3">
    <inertial>
      <origin
        xyz="-2.2204E-16 -2.2204E-16 0.020599"
        rpy="0 0 0" />
      <mass
        value="1" />
      <inertia
        ixx="0.0015346"
        ixy="4.4723E-19"
        ixz="-9.1607E-20"
        iyy="0.0015346"
        iyz="1.9984E-20"
        izz="0.0021859" />
    </inertial>
    <visual>
      <origin
        xyz="0 0 0"
        rpy="0 0 0" />
      <geometry>
        <mesh
          filename="file://$(find articubot_one)/meshes/wheel3.STL" />
      </geometry>
      <material
        name="">
        <color
          rgba="0.79216 0.81961 0.93333 1" />
      </material>
    </visual>
    <collision>
      <origin
        xyz="0 0 0"
        rpy="0 0 0" />
      <geometry>
        <mesh
		filename="file://$(find articubot_one)/meshes/wheel3.STL" />
      </geometry>
    </collision>
  </link>
  <joint
    name="wheel3_joint"
    type="continuous">
    <origin
      xyz="0.23 0.285 -0.2"
      rpy="-1.5708 0 0" />
    <parent
      link="chassis" />
    <child
      link="wheel3" />
    <axis
      xyz="0 0 -1" />
    
  </joint>
  
  <link
    name="wheel4">
    <inertial>
      <origin
        xyz="-2.2204E-16 -2.2204E-16 0.020599"
        rpy="0 0 0" />
      <mass
        value="1" />
      <inertia
        ixx="0.0015346"
        ixy="8.1315E-20"
        ixz="9.4691E-20"
        iyy="0.0015346"
        iyz="-1.1469E-19"
        izz="0.0021859" />
    </inertial>
    <visual>
      <origin
        xyz="0 0 0"
        rpy="0 0 0" />
      <geometry>
        <mesh
          filename="file://$(find articubot_one)/meshes/wheel4.STL" />
      </geometry>
      <material
        name="">
        <color
          rgba="0.79216 0.81961 0.93333 1" />
      </material>
    </visual>
    <collision>
      <origin
        xyz="0 0 0"
        rpy="0 0 0" />
      <geometry>
        <mesh
          filename="file://$(find articubot_one)/meshes/wheel4.STL" />
      </geometry>
    </collision>
  </link>
  <joint
    name="wheel4_joint"
    type="continuous">
    <origin
      xyz="-0.23 0.285 -0.2"
      rpy="-1.5708 0 0" />
    <parent
      link="chassis" />
    <child
      link="wheel4" />
    <axis
      xyz="0 0 -1" />
   
  </joint>
  <link
    name="laser_frame">
    <inertial>
      <origin
        xyz="0 0 0"
        rpy="0 0 0" />
      <mass
        value="0.8" />
      <inertia
        ixx="0"
        ixy="0"
        ixz="0"
        iyy="0"
        iyz="0"
        izz="0" />
    </inertial>
    <visual>
      <origin
        xyz="0 0 0"
        rpy="0 0 0" />
      <geometry>
        <mesh
          filename="file://$(find articubot_one)/meshes/lidar.STL" />
      </geometry>
      <material
        name="">
        <color
          rgba="1 1 1 1" />
      </material>
    </visual>
    <collision>
      <origin
        xyz="0 0 0"
        rpy="0 0 0" />
      <geometry>
        <mesh
          filename="file://$(find articubot_one)/meshes/lidar.STL" />
      </geometry>
    </collision>
  </link>
  <joint
    name="lidar_joint"
    type="fixed">
    <origin
      xyz="0.41158 0 -0.004"
      rpy="0 0 0" />
    <parent
      link="chassis" />
    <child
      link="laser_frame" />
    <axis
      xyz="0 0 0" />
  </joint>
</robot>
